multiprocessing.pool.RemoteTraceback: 
"""
Traceback (most recent call last):
  File "/usr/lib/python3.8/multiprocessing/pool.py", line 125, in worker
    result = (True, func(*args, **kwds))
  File "/usr/lib/python3.8/multiprocessing/pool.py", line 48, in mapstar
    return list(map(*args))
  File "launch.py", line 11, in worker
    run.run()
  File "/data/home/seoyongs/cmpt450/a1-yonghyukseo/run.py", line 254, in run
    proc = subprocess.Popen(self.command, cwd = cwd)
  File "/usr/lib/python3.8/subprocess.py", line 858, in __init__
    self._execute_child(args, executable, preexec_fn, close_fds,
  File "/usr/lib/python3.8/subprocess.py", line 1639, in _execute_child
    self.pid = _posixsubprocess.fork_exec(
TypeError: expected str, bytes or os.PathLike object, not list
"""

The above exception was the direct cause of the following exception:

Traceback (most recent call last):
  File "launch.py", line 73, in <module>
    pool.map(worker,jobs)
  File "/usr/lib/python3.8/multiprocessing/pool.py", line 364, in map
    return self._map_async(func, iterable, mapstar, chunksize).get()
  File "/usr/lib/python3.8/multiprocessing/pool.py", line 771, in get
    raise self._value
TypeError: expected str, bytes or os.PathLike object, not list
srun: error: ARCH-750: task 0: Exited with exit code 1
